Workbook

Sheet 使用说明
B2: 钢铁数字化系统 · 首年财务预测模型 v1.0
B4: 适用对象 | C4: 老板 / 财务 / 营销负责人 / 投资人
B5: 使用步骤 | C5: ① 打开『关键假设』，按黄色单元格调参数（线索量/转化率/客单价/人力等） ② 切换『月度漏斗』『月度收入』『月度成本』『月度现金流』查看自动结果 ③ 『损益与回本』给你 3 个核心数：首年损益、单月转正月份、累计回本月份 ④ 『三档情景对比』给你保守/基准/乐观对比
B6: 假设解释 | C6: • 线索来源：地推/老板局/合伙人/灯塔厂转介绍/内容营销 5 类 • 转化率：MQL→SQL→POC→签约 4 段漏斗 • 客单价：种子/经营/旗舰 3 档比例 + 12 期分期模式（默认 70%） • 续费：月租按客户保留率累计 MRR • 成本：人力 + 营销 + 老板局 + 工具 + 应急
B7: 修改边界 | C7: 只改黄色单元格；公式和表头不要动
B8: 注意 | C8: 1. 数字仅基于行业基准 + 钢铁 SaaS 经验估算，**不是承诺** 2. 实际偏差 ±30% 属正常；偏差 >50% 时及时复盘 3. 建议每月用真实数据替换『假设月数据』，做 Forward Forecast

Sheet 关键假设
B2: 关键假设输入区（黄色 = 可调）
B4: 一、线索获取（每月）
B5: 地推线索数（每月） | C5: 80 | D5: 条/月 | E5: 1-2 个地推人员稳定产出
B6: 老板局线索数（每月） | C6: 15 | D6: 条/月 | E6: 1.5 月办 1 场，每场 12 人
B7: 合伙人推荐线索（每月） | C7: 25 | D7: 条/月 | E7: 100 个合伙人后稳定
B8: 灯塔厂转介绍（每月） | C8: 8 | D8: 条/月 | E8: 灯塔厂上线后才有
B9: 内容/线上线索（每月） | C9: 20 | D9: 条/月 | E9: 公众号/抖音/视频号
B11: 二、漏斗转化率
B12: 线索 → MQL（添加微信） | C12: 0.3 | D12: % | E12: 整体均值
B13: MQL → SQL（约访成功） | C13: 0.4 | D13: %
B14: SQL → POC | C14: 0.5 | D14: % | E14: 上门诊断后启动 POC
B15: POC → 签约 | C15: 0.55 | D15: % | E15: POC 成功率
B17: 三、客单价分布
B18: 种子版占比 | C18: 0.3 | D18: %
B19: 经营版占比 | C19: 0.55 | D19: %
B20: 旗舰版占比 | C20: 0.15 | D20: %
B21: 种子版均价(实施) | C21: 30000 | D21: 元 | E21: 钢管/镀锌/开平/一体加权
B22: 种子版均价(月租) | C22: 5000 | D22: 元
B23: 经营版均价(实施) | C23: 90000 | D23: 元
B24: 经营版均价(月租) | C24: 12000 | D24: 元
B25: 旗舰版均价(实施) | C25: 230000 | D25: 元
B26: 旗舰版均价(月租) | C26: 35000 | D26: 元
B27: 12 期分期客户占比 | C27: 0.7 | D27: % | E27: 选 12 期分期的客户比例
B28: 年付折扣客户占比 | C28: 0.1 | D28: % | E28: 选年付 9 折的比例
B30: 四、续费与流失
B31: 月度客户流失率 | C31: 0.015 | D31: % | E31: 1.5% / 月，相当于年流失 16%
B33: 五、人力成本（月薪含五险一金）
B34: CMO（前 6 月空缺，老板兼） | C34: 0 | D34: 元 | E34: 前 6 月不计；7 月起按 40000
B35: 销售总监 × 2 | C35: 44000 | D35: 元 | E35: 每人 22000
B36: 销售 × 2-4 | C36: 48000 | D36: 元 | E36: 前 6 月 2 人、7 月起 4 人，简化按 4
B37: 售前 × 2 | C37: 28000 | D37: 元
B38: 实施顾问 × 2 | C38: 32000 | D38: 元
B39: 地推 × 2 | C39: 14000 | D39: 元 | E39: 底薪，提成在动作变量
B40: 销售运营经理 | C40: 12000 | D40: 元
B41: 合伙人运营专员 | C41: 10000 | D41: 元
B42: 市场/内容 | C42: 13000 | D42: 元
B43: 行政/商务 | C43: 8000 | D43: 元
B45: 六、营销成本（每月）
B46: 内容制作（公众号/视频） | C46: 20000 | D46: 元/月
B47: 地推物料 + 提成 | C47: 15000 | D47: 元/月
...

Sheet 月度漏斗
A1: 月度漏斗（自动计算 12 个月）
A3: 指标 | B3: M1 | C3: M2 | D3: M3 | E3: M4 | F3: M5 | G3: M6 | H3: M7 | I3: M8 | J3: M9 | K3: M10 | L3: M11 | M3: M12 | N3: 全年合计
A4: 地推线索 | B4: =ROUND('关键假设'!$C$5*0.3,0) | C4: =ROUND('关键假设'!$C$5*0.45,0) | D4: =ROUND('关键假设'!$C$5*0.6,0) | E4: =ROUND('关键假设'!$C$5*0.75,0) | F4: =ROUND('关键假设'!$C$5*0.85,0) | G4: =ROUND('关键假设'!$C$5*1.0,0) | H4: =ROUND('关键假设'!$C$5*1.1,0) | I4: =ROUND('关键假设'!$C$5*1.2,0) | J4: =ROUND('关键假设'!$C$5*1.3,0) | K4: =ROUND('关键假设'!$C$5*1.35,0) | L4: =ROUND('关键假设'!$C$5*1.4,0) | M4: =ROUND('关键假设'!$C$5*1.45,0) | N4: =SUM(B4:M4)
A5: 老板局线索 | B5: =ROUND('关键假设'!$C$6*0,0) | C5: =ROUND('关键假设'!$C$6*0,0) | D5: =ROUND('关键假设'!$C$6*0.5,0) | E5: =ROUND('关键假设'!$C$6*0.5,0) | F5: =ROUND('关键假设'!$C$6*1,0) | G5: =ROUND('关键假设'!$C$6*1,0) | H5: =ROUND('关键假设'!$C$6*1,0) | I5: =ROUND('关键假设'!$C$6*1,0) | J5: =ROUND('关键假设'!$C$6*1,0) | K5: =ROUND('关键假设'!$C$6*1,0) | L5: =ROUND('关键假设'!$C$6*1,0) | M5: =ROUND('关键假设'!$C$6*1,0) | N5: =SUM(B5:M5)
A6: 合伙人推荐 | B6: =ROUND('关键假设'!$C$7*0.1,0) | C6: =ROUND('关键假设'!$C$7*0.2,0) | D6: =ROUND('关键假设'!$C$7*0.4,0) | E6: =ROUND('关键假设'!$C$7*0.6,0) | F6: =ROUND('关键假设'!$C$7*0.7,0) | G6: =ROUND('关键假设'!$C$7*0.8,0) | H6: =ROUND('关键假设'!$C$7*0.9,0) | I6: =ROUND('关键假设'!$C$7*1.0,0) | J6: =ROUND('关键假设'!$C$7*1.0,0) | K6: =ROUND('关键假设'!$C$7*1.0,0) | L6: =ROUND('关键假设'!$C$7*1.0,0) | M6: =ROUND('关键假设'!$C$7*1.0,0) | N6: =SUM(B6:M6)
A7: 灯塔厂转介绍 | B7: =ROUND('关键假设'!$C$8*0,0) | C7: =ROUND('关键假设'!$C$8*0,0) | D7: =ROUND('关键假设'!$C$8*0,0) | E7: =ROUND('关键假设'!$C$8*0,0) | F7: =ROUND('关键假设'!$C$8*0.3,0) | G7: =ROUND('关键假设'!$C$8*0.5,0) | H7: =ROUND('关键假设'!$C$8*0.8,0) | I7: =ROUND('关键假设'!$C$8*1.0,0) | J7: =ROUND('关键假设'!$C$8*1.0,0) | K7: =ROUND('关键假设'!$C$8*1.0,0) | L7: =ROUND('关键假设'!$C$8*1.0,0) | M7: =ROUND('关键假设'!$C$8*1.0,0) | N7: =SUM(B7:M7)
A8: 内容/线上 | B8: =ROUND('关键假设'!$C$9*0.3,0) | C8: =ROUND('关键假设'!$C$9*0.45,0) | D8: =ROUND('关键假设'!$C$9*0.6,0) | E8: =ROUND('关键假设'!$C$9*0.75,0) | F8: =ROUND('关键假设'!$C$9*0.85,0) | G8: =ROUND('关键假设'!$C$9*1.0,0) | H8: =ROUND('关键假设'!$C$9*1.1,0) | I8: =ROUND('关键假设'!$C$9*1.2,0) | J8: =ROUND('关键假设'!$C$9*1.3,0) | K8: =ROUND('关键假设'!$C$9*1.35,0) | L8: =ROUND('关键假设'!$C$9*1.4,0) | M8: =ROUND('关键假设'!$C$9*1.45,0) | N8: =SUM(B8:M8)
A9: 月度总线索 | B9: =SUM(B4:B8) | C9: =SUM(C4:C8) | D9: =SUM(D4:D8) | E9: =SUM(E4:E8) | F9: =SUM(F4:F8) | G9: =SUM(G4:G8) | H9: =SUM(H4:H8) | I9: =SUM(I4:I8) | ... M9: =SUM(M4:M8) | N9: =SUM(B9:M9)
A10: MQL（添加微信） | B10: =ROUND(B9*'关键假设'!$C$12,0) | C10: =ROUND(C9*'关键假设'!$C$12,0) | D10: =ROUND(D9*'关键假设'!$C$12,0) | E10: =ROUND(E9*'关键假设'!$C$12,0) | F10: =ROUND(F9*'关键假设'!$C$12,0) | G10: =ROUND(G9*'关键假设'!$C$12,0) | H10: =ROUND(H9*'关键假设'!$C$12,0) | I10: =ROUND(I9*'关键假设'!$C$12,0) | ... M10: =ROUND(M9*'关键假设'!$C$12,0) | N10: =SUM(B10:M10)
A11: SQL（约访成功） | B11: =ROUND(B10*'关键假设'!$C$13,0) | C11: =ROUND(C10*'关键假设'!$C$13,0) | D11: =ROUND(D10*'关键假设'!$C$13,0) | E11: =ROUND(E10*'关键假设'!$C$13,0) | F11: =ROUND(F10*'关键假设'!$C$13,0) | G11: =ROUND(G10*'关键假设'!$C$13,0) | H11: =ROUND(H10*'关键假设'!$C$13,0) | I11: =ROUND(I10*'关键假设'!$C$13,0) | ... M11: =ROUND(M10*'关键假设'!$C$13,0) | N11: =SUM(B11:M11)
A12: POC 启动 | B12: =ROUND(B11*'关键假设'!$C$14,0) | C12: =ROUND(C11*'关键假设'!$C$14,0) | D12: =ROUND(D11*'关键假设'!$C$14,0) | E12: =ROUND(E11*'关键假设'!$C$14,0) | F12: =ROUND(F11*'关键假设'!$C$14,0) | G12: =ROUND(G11*'关键假设'!$C$14,0) | H12: =ROUND(H11*'关键假设'!$C$14,0) | I12: =ROUND(I11*'关键假设'!$C$14,0) | ... M12: =ROUND(M11*'关键假设'!$C$14,0) | N12: =SUM(B12:M12)
A13: 签约 | B13: =ROUND(B12*'关键假设'!$C$15,0) | C13: =ROUND(C12*'关键假设'!$C$15,0) | D13: =ROUND(D12*'关键假设'!$C$15,0) | E13: =ROUND(E12*'关键假设'!$C$15,0) | F13: =ROUND(F12*'关键假设'!$C$15,0) | G13: =ROUND(G12*'关键假设'!$C$15,0) | H13: =ROUND(H12*'关键假设'!$C$15,0) | I13: =ROUND(I12*'关键假设'!$C$15,0) | ... M13: =ROUND(M12*'关键假设'!$C$15,0) | N13: =SUM(B13:M13)

Sheet 月度收入
A1: 月度收入（自动计算）
A3: 指标 | B3: M1 | C3: M2 | D3: M3 | E3: M4 | F3: M5 | G3: M6 | H3: M7 | I3: M8 | J3: M9 | K3: M10 | L3: M11 | M3: M12 | N3: 全年合计
A4: 月度签约数 | B4: ='月度漏斗'!B13 | C4: ='月度漏斗'!C13 | D4: ='月度漏斗'!D13 | E4: ='月度漏斗'!E13 | F4: ='月度漏斗'!F13 | G4: ='月度漏斗'!G13 | H4: ='月度漏斗'!H13 | I4: ='月度漏斗'!I13 | ... M4: ='月度漏斗'!M13 | N4: =SUM(B4:M4)
A5: 种子版签约 | B5: =B4*'关键假设'!$C$18 | C5: =C4*'关键假设'!$C$18 | D5: =D4*'关键假设'!$C$18 | E5: =E4*'关键假设'!$C$18 | F5: =F4*'关键假设'!$C$18 | G5: =G4*'关键假设'!$C$18 | H5: =H4*'关键假设'!$C$18 | I5: =I4*'关键假设'!$C$18 | ... M5: =M4*'关键假设'!$C$18 | N5: =SUM(B5:M5)
A6: 经营版签约 | B6: =B4*'关键假设'!$C$19 | C6: =C4*'关键假设'!$C$19 | D6: =D4*'关键假设'!$C$19 | E6: =E4*'关键假设'!$C$19 | F6: =F4*'关键假设'!$C$19 | G6: =G4*'关键假设'!$C$19 | H6: =H4*'关键假设'!$C$19 | I6: =I4*'关键假设'!$C$19 | ... M6: =M4*'关键假设'!$C$19 | N6: =SUM(B6:M6)
A7: 旗舰版签约 | B7: =B4*'关键假设'!$C$20 | C7: =C4*'关键假设'!$C$20 | D7: =D4*'关键假设'!$C$20 | E7: =E4*'关键假设'!$C$20 | F7: =F4*'关键假设'!$C$20 | G7: =G4*'关键假设'!$C$20 | H7: =H4*'关键假设'!$C$20 | I7: =I4*'关键假设'!$C$20 | ... M7: =M4*'关键假设'!$C$20 | N7: =SUM(B7:M7)
A8: 新增实施费合同额 | B8: =B5*'关键假设'!$C$21+B6*'关键假设'!$C$23+B7*'关键假设'!$C$25 | C8: =C5*'关键假设'!$C$21+C6*'关键假设'!$C$23+C7*'关键假设'!$C$25 | D8: =D5*'关键假设'!$C$21+D6*'关键假设'!$C$23+D7*'关键假设'!$C$25 | E8: =E5*'关键假设'!$C$21+E6*'关键假设'!$C$23+E7*'关键假设'!$C$25 | F8: =F5*'关键假设'!$C$21+F6*'关键假设'!$C$23+F7*'关键假设'!$C$25 | G8: =G5*'关键假设'!$C$21+G6*'关键假设'!$C$23+G7*'关键假设'!$C$25 | H8: =H5*'关键假设'!$C$21+H6*'关键假设'!$C$23+H7*'关键假设'!$C$25 | I8: =I5*'关键假设'!$C$21+I6*'关键假设'!$C$23+I7*'关键假设'!$C$25 | ... M8: =M5*'关键假设'!$C$21+M6*'关键假设'!$C$23+M7*'关键假设'!$C$25 | N8: =SUM(B8:M8)
A9: 当月新增 MRR | B9: =B5*'关键假设'!$C$22+B6*'关键假设'!$C$24+B7*'关键假设'!$C$26 | C9: =C5*'关键假设'!$C$22+C6*'关键假设'!$C$24+C7*'关键假设'!$C$26 | D9: =D5*'关键假设'!$C$22+D6*'关键假设'!$C$24+D7*'关键假设'!$C$26 | E9: =E5*'关键假设'!$C$22+E6*'关键假设'!$C$24+E7*'关键假设'!$C$26 | F9: =F5*'关键假设'!$C$22+F6*'关键假设'!$C$24+F7*'关键假设'!$C$26 | G9: =G5*'关键假设'!$C$22+G6*'关键假设'!$C$24+G7*'关键假设'!$C$26 | H9: =H5*'关键假设'!$C$22+H6*'关键假设'!$C$24+H7*'关键假设'!$C$26 | I9: =I5*'关键假设'!$C$22+I6*'关键假设'!$C$24+I7*'关键假设'!$C$26 | ... M9: =M5*'关键假设'!$C$22+M6*'关键假设'!$C$24+M7*'关键假设'!$C$26 | N9: =SUM(B9:M9)
A10: 累计 MRR（含流失） | B10: =B9 | C10: =B10*(1-'关键假设'!$C$31)+C9 | D10: =C10*(1-'关键假设'!$C$31)+D9 | E10: =D10*(1-'关键假设'!$C$31)+E9 | F10: =E10*(1-'关键假设'!$C$31)+F9 | G10: =F10*(1-'关键假设'!$C$31)+G9 | H10: =G10*(1-'关键假设'!$C$31)+H9 | I10: =H10*(1-'关键假设'!$C$31)+I9 | J10: =I10*(1-'关键假设'!$C$31)+J9 | ... M10: =L10*(1-'关键假设'!$C$31)+M9 | N10: —
A11: 月度月租收入 | B11: =B10 | C11: =C10 | D11: =D10 | E11: =E10 | F11: =F10 | G11: =G10 | H11: =H10 | I11: =I10 | ... M11: =M10 | N11: =SUM(B11:M11)
A12: 月度实施费现金回收 | B12: =B8*0.3 | C12: =C8*0.3+B8*0.5 | D12: =D8*0.3+C8*0.5 | E12: =E8*0.3+D8*0.5+B8*0.2 | F12: =F8*0.3+E8*0.5+C8*0.2 | G12: =G8*0.3+F8*0.5+D8*0.2 | H12: =H8*0.3+G8*0.5+E8*0.2 | I12: =I8*0.3+H8*0.5+F8*0.2 | J12: =J8*0.3+I8*0.5+G8*0.2 | K12: =K8*0.3+J8*0.5+H8*0.2 | L12: =L8*0.3+K8*0.5+I8*0.2 | M12: =M8*0.3+L8*0.5+J8*0.2 | N12: =SUM(B12:M12)
A13: 月度总现金收入 | B13: =B11+B12 | C13: =C11+C12 | D13: =D11+D12 | E13: =E11+E12 | F13: =F11+F12 | G13: =G11+G12 | H13: =H11+H12 | I13: =I11+I12 | ... M13: =M11+M12 | N13: =SUM(B13:M13)

Sheet 月度成本
A1: 月度成本（自动计算）
A3: 指标 | B3: M1 | C3: M2 | D3: M3 | E3: M4 | F3: M5 | G3: M6 | H3: M7 | I3: M8 | J3: M9 | K3: M10 | L3: M11 | M3: M12 | N3: 全年合计
A4: 人力成本 | B4: =SUM('关键假设'!$C$35:$C$43) | C4: =SUM('关键假设'!$C$35:$C$43) | D4: =SUM('关键假设'!$C$35:$C$43) | E4: =SUM('关键假设'!$C$35:$C$43) | F4: =SUM('关键假设'!$C$35:$C$43) | G4: =SUM('关键假设'!$C$35:$C$43) | H4: =SUM('关键假设'!$C$35:$C$43) + 40000 | I4: =SUM('关键假设'!$C$35:$C$43) + 40000 | J4: =SUM('关键假设'!$C$35:$C$43) + 40000 | K4: =SUM('关键假设'!$C$35:$C$43) + 40000 | L4: =SUM('关键假设'!$C$35:$C$43) + 40000 | M4: =SUM('关键假设'!$C$35:$C$43) + 40000 | N4: =SUM(B4:M4)
A5: 营销固定成本 | B5: =SUM('关键假设'!$C$46:$C$50) | C5: =SUM('关键假设'!$C$46:$C$50) | D5: =SUM('关键假设'!$C$46:$C$50) | E5: =SUM('关键假设'!$C$46:$C$50) | F5: =SUM('关键假设'!$C$46:$C$50) | G5: =SUM('关键假设'!$C$46:$C$50) | H5: =SUM('关键假设'!$C$46:$C$50) | I5: =SUM('关键假设'!$C$46:$C$50) | ... M5: =SUM('关键假设'!$C$46:$C$50) | N5: =SUM(B5:M5)
A6: 老板局费用 | B6: =0 | C6: =0 | D6: ='关键假设'!$C$53 | E6: =0 | F6: =0 | G6: ='关键假设'!$C$53 | H6: =0 | I6: =0 | J6: ='关键假设'!$C$53 | K6: =0 | L6: =0 | M6: ='关键假设'!$C$53 | N6: =SUM(B6:M6)
A7: 灯塔厂补贴(摊销) | B7: ='关键假设'!$C$57*'关键假设'!$C$58/'关键假设'!$C$59 | C7: ='关键假设'!$C$57*'关键假设'!$C$58/'关键假设'!$C$59 | D7: ='关键假设'!$C$57*'关键假设'!$C$58/'关键假设'!$C$59 | E7: ='关键假设'!$C$57*'关键假设'!$C$58/'关键假设'!$C$59 | F7: ='关键假设'!$C$57*'关键假设'!$C$58/'关键假设'!$C$59 | G7: ='关键假设'!$C$57*'关键假设'!$C$58/'关键假设'!$C$59 | H7: ='关键假设'!$C$57*'关键假设'!$C$58/'关键假设'!$C$59 | I7: ='关键假设'!$C$57*'关键假设'!$C$58/'关键假设'!$C$59 | ... M7: ='关键假设'!$C$57*'关键假设'!$C$58/'关键假设'!$C$59 | N7: =SUM(B7:M7)
A8: 销售/售前提成 | B8: ='月度收入'!B8*('关键假设'!$C$62+'关键假设'!$C$64) + '月度收入'!B11*('关键假设'!$C$63+'关键假设'!$C$65) | C8: ='月度收入'!C8*('关键假设'!$C$62+'关键假设'!$C$64) + '月度收入'!C11*('关键假设'!$C$63+'关键假设'!$C$65) | D8: ='月度收入'!D8*('关键假设'!$C$62+'关键假设'!$C$64) + '月度收入'!D11*('关键假设'!$C$63+'关键假设'!$C$65) | E8: ='月度收入'!E8*('关键假设'!$C$62+'关键假设'!$C$64) + '月度收入'!E11*('关键假设'!$C$63+'关键假设'!$C$65) | F8: ='月度收入'!F8*('关键假设'!$C$62+'关键假设'!$C$64) + '月度收入'!F11*('关键假设'!$C$63+'关键假设'!$C$65) | G8: ='月度收入'!G8*('关键假设'!$C$62+'关键假设'!$C$64) + '月度收入'!G11*('关键假设'!$C$63+'关键假设'!$C$65) | H8: ='月度收入'!H8*('关键假设'!$C$62+'关键假设'!$C$64) + '月度收入'!H11*('关键假设'!$C$63+'关键假设'!$C$65) | I8: ='月度收入'!I8*('关键假设'!$C$62+'关键假设'!$C$64) + '月度收入'!I11*('关键假设'!$C$63+'关键假设'!$C$65) | ... M8: ='月度收入'!M8*('关键假设'!$C$62+'关键假设'!$C$64) + '月度收入'!M11*('关键假设'!$C$63+'关键假设'!$C$65) | N8: =SUM(B8:M8)
A9: 应急/杂费 | B9: 5000 | C9: 5000 | D9: 5000 | E9: 5000 | F9: 5000 | G9: 5000 | H9: 5000 | I9: 5000 | J9: 5000 | K9: 5000 | L9: 5000 | M9: 5000 | N9: =SUM(B9:M9)
A10: 月度总成本 | B10: =SUM(B4:B9) | C10: =SUM(C4:C9) | D10: =SUM(D4:D9) | E10: =SUM(E4:E9) | F10: =SUM(F4:F9) | G10: =SUM(G4:G9) | H10: =SUM(H4:H9) | I10: =SUM(I4:I9) | ... M10: =SUM(M4:M9) | N10: =SUM(B10:M10)

Sheet 月度现金流
A1: 月度现金流（自动计算）
A3: 指标 | B3: M1 | C3: M2 | D3: M3 | E3: M4 | F3: M5 | G3: M6 | H3: M7 | I3: M8 | J3: M9 | K3: M10 | L3: M11 | M3: M12 | N3: 全年合计
A4: 月度现金收入 | B4: ='月度收入'!B13 | C4: ='月度收入'!C13 | D4: ='月度收入'!D13 | E4: ='月度收入'!E13 | F4: ='月度收入'!F13 | G4: ='月度收入'!G13 | H4: ='月度收入'!H13 | I4: ='月度收入'!I13 | ... M4: ='月度收入'!M13 | N4: =SUM(B4:M4)
A5: 月度总成本 | B5: ='月度成本'!B10 | C5: ='月度成本'!C10 | D5: ='月度成本'!D10 | E5: ='月度成本'!E10 | F5: ='月度成本'!F10 | G5: ='月度成本'!G10 | H5: ='月度成本'!H10 | I5: ='月度成本'!I10 | ... M5: ='月度成本'!M10 | N5: =SUM(B5:M5)
A6: 月度净现金 | B6: =B4-B5 | C6: =C4-C5 | D6: =D4-D5 | E6: =E4-E5 | F6: =F4-F5 | G6: =G4-G5 | H6: =H4-H5 | I6: =I4-I5 | ... M6: =M4-M5 | N6: =SUM(B6:M6)
A7: 累计现金净额 | B7: =B6 | C7: =B7+C6 | D7: =C7+D6 | E7: =D7+E6 | F7: =E7+F6 | G7: =F7+G6 | H7: =G7+H6 | I7: =H7+I6 | J7: =I7+J6 | ... M7: =L7+M6

Sheet 损益与回本
B2: 首年损益与回本分析
B4: 全年现金收入合计 | C4: ='月度现金流'!N4 | D4: 实施费现金 + 月租收入
B5: 全年现金成本合计 | C5: ='月度现金流'!N5 | D5: 人力 + 营销 + 老板局 + 提成 + 应急
B6: 全年净现金（首年损益） | C6: ='月度现金流'!N6 | D6: 正 = 自我造血；负 = 需要补贴
B7: 第 12 月累计 MRR | C7: ='月度收入'!M11 | D7: 月经常性收入，是公司估值的关键
B8: 年化 MRR（×12） | C8: ='月度收入'!M11*12 | D8: ARR
B9: 第 12 月累计签约客户数 | C9: =SUM('月度漏斗'!B13:M13) | D9: 首年签约总数
B10: 单月净现金转正月份 | C10: =IFERROR(MATCH(TRUE,('月度现金流'!B6:M6>0),0),"未转正") | D10: 首次单月现金为正的月份（数字 1-12）
B11: 累计现金净额转正月份 | C11: =IFERROR(MATCH(TRUE,('月度现金流'!B7:M7>0),0),"未在首年回本") | D11: 首次累计现金为正的月份
B14: 解读建议： • 首年现金净额为负属正常 —— B 端 SaaS 第 1 年通常烧钱 • 重点看「累计 MRR」和「ARR」 —— 这两个数字决定了第 2 年起的爆发能力 • 若单月净现金转正在 M9 之前 → 极优秀 • 若 M12 仍未转正 → 检查转化率/客单价/人力规模是否合理 • 累计现金回本通常发生在第 13-18 月，属于行业常态

Sheet 三档情景对比
B2: 保守 / 基准 / 乐观 三档情景对比（手工调假设页参数验证）
B4: 情景 | C4: 线索量调整 | D4: 转化率调整 | E4: 首年净现金（基准） | F4: 操作建议
B5: 保守 | C5: × 0.7 | D5: × 0.7 | E5: （手动验证） | F5: 把『关键假设』里地推/老板局/合伙人/内容线索数 ×0.7，再把 4 段转化率 ×0.7
B6: 基准 | C6: × 1.0 | D6: × 1.0 | E6: ='损益与回本'!C6 | F6: 默认参数（建议起步用此情景）
B7: 乐观 | C7: × 1.3 | D7: × 1.2 | E7: （手动验证） | F7: 把『关键假设』里所有线索数 ×1.3，转化率 ×1.2，目标超额完成
B10: 使用建议： 1. 用基准跑一次完整结果，记录关键数字 2. 切换到保守 / 乐观，看现金流压力区间 3. 决策时按『保守 = 公司能扛』标准调整融资 / 现金储备
